<?xml version="1.0" ?>
<!-- =================================================================================== -->
<!-- |    This document was autogenerated by xacro from /home/stewart/Robotics/ros-qp4/src/qp4_description/urdf/qp4.xacro | -->
<!-- |    EDITING THIS FILE BY HAND IS NOT RECOMMENDED                                 | -->
<!-- =================================================================================== -->
<robot name="qp4" xmlns:xacro="http://www.ros.org/wiki/xacro">
  <material name="black">
    <color rgba="0.0 0.0 0.0 1.0"/>
  </material>
  <material name="blue">
    <color rgba="0.0 0.0 0.8 1.0"/>
  </material>
  <material name="green">
    <color rgba="0.0 0.8 0.0 1.0"/>
  </material>
  <material name="gray">
    <color rgba="0.7 0.7 0.7 1.0"/>
  </material>
  <material name="darkgray">
    <color rgba="0.3 0.3 0.3 1.0"/>
  </material>
  <material name="red">
    <color rgba="0.8 0.0 0.0 1.0"/>
  </material>
  <material name="white">
    <color rgba="1.0 1.0 1.0 1.0"/>
  </material>
  <material name="yellow">
    <color rgba="0.8 0.8 0.0 1.0"/>
  </material>
  <gazebo>
    <plugin filename="libgazebo_ros_control.so" name="gazebo_ros_control">
      <robotNamespace>/</robotNamespace>
      <robotSimType>gazebo_ros_control/DefaultRobotHWSim</robotSimType>
    </plugin>
  </gazebo>
  <transmission name="back_right_hip_swing_joint_tran">
    <type>transmission_interface/SimpleTransmission</type>
    <joint name="back_right_hip_swing_joint">
      <hardwareInterface>EffortJointInterface</hardwareInterface>
    </joint>
    <actuator name="back_right_hip_swing_joint_motor">
      <hardwareInterface>EffortJointInterface</hardwareInterface>
      <mechanicalReduction>1</mechanicalReduction>
    </actuator>
  </transmission>
  <transmission name="back_left_hip_swing_joint_tran">
    <type>transmission_interface/SimpleTransmission</type>
    <joint name="back_left_hip_swing_joint">
      <hardwareInterface>EffortJointInterface</hardwareInterface>
    </joint>
    <actuator name="back_left_hip_swing_joint_motor">
      <hardwareInterface>EffortJointInterface</hardwareInterface>
      <mechanicalReduction>1</mechanicalReduction>
    </actuator>
  </transmission>
  <transmission name="front_right_hip_swing_joint_tran">
    <type>transmission_interface/SimpleTransmission</type>
    <joint name="front_right_hip_swing_joint">
      <hardwareInterface>EffortJointInterface</hardwareInterface>
    </joint>
    <actuator name="front_right_hip_swing_joint_motor">
      <hardwareInterface>EffortJointInterface</hardwareInterface>
      <mechanicalReduction>1</mechanicalReduction>
    </actuator>
  </transmission>
  <transmission name="front_left_hip_swing_joint_tran">
    <type>transmission_interface/SimpleTransmission</type>
    <joint name="front_left_hip_swing_joint">
      <hardwareInterface>EffortJointInterface</hardwareInterface>
    </joint>
    <actuator name="front_left_hip_swing_joint_motor">
      <hardwareInterface>EffortJointInterface</hardwareInterface>
      <mechanicalReduction>1</mechanicalReduction>
    </actuator>
  </transmission>
  <transmission name="back_right_hip_lateral_joint_tran">
    <type>transmission_interface/SimpleTransmission</type>
    <joint name="back_right_hip_lateral_joint">
      <hardwareInterface>EffortJointInterface</hardwareInterface>
    </joint>
    <actuator name="back_right_hip_lateral_joint_motor">
      <hardwareInterface>EffortJointInterface</hardwareInterface>
      <mechanicalReduction>1</mechanicalReduction>
    </actuator>
  </transmission>
  <transmission name="back_left_hip_lateral_joint_tran">
    <type>transmission_interface/SimpleTransmission</type>
    <joint name="back_left_hip_lateral_joint">
      <hardwareInterface>EffortJointInterface</hardwareInterface>
    </joint>
    <actuator name="back_left_hip_lateral_joint_motor">
      <hardwareInterface>EffortJointInterface</hardwareInterface>
      <mechanicalReduction>1</mechanicalReduction>
    </actuator>
  </transmission>
  <transmission name="front_right_hip_lateral_joint_tran">
    <type>transmission_interface/SimpleTransmission</type>
    <joint name="front_right_hip_lateral_joint">
      <hardwareInterface>EffortJointInterface</hardwareInterface>
    </joint>
    <actuator name="front_right_hip_lateral_joint_motor">
      <hardwareInterface>EffortJointInterface</hardwareInterface>
      <mechanicalReduction>1</mechanicalReduction>
    </actuator>
  </transmission>
  <transmission name="front_left_hip_lateral_joint_tran">
    <type>transmission_interface/SimpleTransmission</type>
    <joint name="front_left_hip_lateral_joint">
      <hardwareInterface>EffortJointInterface</hardwareInterface>
    </joint>
    <actuator name="front_left_hip_lateral_joint_motor">
      <hardwareInterface>EffortJointInterface</hardwareInterface>
      <mechanicalReduction>1</mechanicalReduction>
    </actuator>
  </transmission>
  <transmission name="back_right_knee_joint_tran">
    <type>transmission_interface/SimpleTransmission</type>
    <joint name="back_right_knee_joint">
      <hardwareInterface>EffortJointInterface</hardwareInterface>
    </joint>
    <actuator name="back_right_knee_joint_motor">
      <hardwareInterface>EffortJointInterface</hardwareInterface>
      <mechanicalReduction>1</mechanicalReduction>
    </actuator>
  </transmission>
  <transmission name="back_left_knee_joint_tran">
    <type>transmission_interface/SimpleTransmission</type>
    <joint name="back_left_knee_joint">
      <hardwareInterface>EffortJointInterface</hardwareInterface>
    </joint>
    <actuator name="back_left_knee_joint_motor">
      <hardwareInterface>EffortJointInterface</hardwareInterface>
      <mechanicalReduction>1</mechanicalReduction>
    </actuator>
  </transmission>
  <transmission name="front_right_knee_joint_tran">
    <type>transmission_interface/SimpleTransmission</type>
    <joint name="front_right_knee_joint">
      <hardwareInterface>EffortJointInterface</hardwareInterface>
    </joint>
    <actuator name="front_right_knee_joint_motor">
      <hardwareInterface>EffortJointInterface</hardwareInterface>
      <mechanicalReduction>1</mechanicalReduction>
    </actuator>
  </transmission>
  <transmission name="front_left_knee_joint_tran">
    <type>transmission_interface/SimpleTransmission</type>
    <joint name="front_left_knee_joint">
      <hardwareInterface>EffortJointInterface</hardwareInterface>
    </joint>
    <actuator name="front_left_knee_joint_motor">
      <hardwareInterface>EffortJointInterface</hardwareInterface>
      <mechanicalReduction>1</mechanicalReduction>
    </actuator>
  </transmission>
  <transmission name="back_right_ankle_joint_tran">
    <type>transmission_interface/SimpleTransmission</type>
    <joint name="back_right_ankle_joint">
      <hardwareInterface>EffortJointInterface</hardwareInterface>
    </joint>
    <actuator name="back_right_ankle_joint_motor">
      <hardwareInterface>EffortJointInterface</hardwareInterface>
      <mechanicalReduction>1</mechanicalReduction>
    </actuator>
  </transmission>
  <transmission name="back_left_ankle_joint_tran">
    <type>transmission_interface/SimpleTransmission</type>
    <joint name="back_left_ankle_joint">
      <hardwareInterface>EffortJointInterface</hardwareInterface>
    </joint>
    <actuator name="back_left_ankle_joint_motor">
      <hardwareInterface>EffortJointInterface</hardwareInterface>
      <mechanicalReduction>1</mechanicalReduction>
    </actuator>
  </transmission>
  <transmission name="front_right_ankle_joint_tran">
    <type>transmission_interface/SimpleTransmission</type>
    <joint name="front_right_ankle_joint">
      <hardwareInterface>EffortJointInterface</hardwareInterface>
    </joint>
    <actuator name="front_right_ankle_joint_motor">
      <hardwareInterface>EffortJointInterface</hardwareInterface>
      <mechanicalReduction>1</mechanicalReduction>
    </actuator>
  </transmission>
  <transmission name="front_left_ankle_joint_tran">
    <type>transmission_interface/SimpleTransmission</type>
    <joint name="front_left_ankle_joint">
      <hardwareInterface>EffortJointInterface</hardwareInterface>
    </joint>
    <actuator name="front_left_ankle_joint_motor">
      <hardwareInterface>EffortJointInterface</hardwareInterface>
      <mechanicalReduction>1</mechanicalReduction>
    </actuator>
  </transmission>
  <!--
		0.003175 = 0.125"
		0.00635 = 0.25"
		0.0127 = 0.5"
		0.0254 = 1"
		0.1524 = 6
		0.254  = 10
		0.2794 = 11"
		0.3048 = 12" 
	-->
  <!-- Torso -->
  <link name="torso_link">
    <visual>
      <geometry>
        <mesh filename="file:///home/stewart/Robotics/ros-qp4/src/qp4_description/../../assets/cad/asb-512.dae" scale="0.001 0.001 0.001"/>
      </geometry>
      <origin rpy="1.57079632679 0 0" xyz="0 -0.1524 0"/>
    </visual>
    <visual>
      <geometry>
        <mesh filename="file:///home/stewart/Robotics/ros-qp4/src/qp4_description/../../assets/cad/asb-11.dae" scale="0.001 0.001 0.001"/>
      </geometry>
      <origin rpy="0 0 1.57079632679" xyz="-0.0125 -0.127 -0.0127"/>
    </visual>
    <visual>
      <geometry>
        <mesh filename="file:///home/stewart/Robotics/ros-qp4/src/qp4_description/../../assets/cad/asb-11.dae" scale="0.001 0.001 0.001"/>
      </geometry>
      <origin rpy="0 0 -1.57079632679" xyz="0.0125 -0.127 -0.0127"/>
    </visual>
    <visual>
      <geometry>
        <mesh filename="file:///home/stewart/Robotics/ros-qp4/src/qp4_description/../../assets/cad/asb-11.dae" scale="0.001 0.001 0.001"/>
      </geometry>
      <origin rpy="0 0 1.57079632679" xyz="-0.0125 0.127 -0.0127"/>
    </visual>
    <visual>
      <geometry>
        <mesh filename="file:///home/stewart/Robotics/ros-qp4/src/qp4_description/../../assets/cad/asb-11.dae" scale="0.001 0.001 0.001"/>
      </geometry>
      <origin rpy="0 0 -1.57079632679" xyz="0.0125 0.127 -0.0127"/>
    </visual>
    <!--
		   	<visual>
	   			<geometry>
					 <box size="0.1016 0.3048 0.0254"/>
	   			</geometry>
				<origin xyz="0 0 -0.0127"/>
	   		</visual>
		   	<visual>
	   			<geometry>
					 <box size="0.0508 0.3048 0.0254"/>
	   			</geometry>
				<origin xyz="-0.0508 0 -0.0254"/>
	   		</visual>
		   	<visual>
	   			<geometry>
					 <box size="0.0508 0.3048 0.0254"/>
	   			</geometry>
				<origin xyz="0.0508 0 -0.0254"/>
	   		</visual>
		-->
    <collision>
      <geometry>
        <box size="0.1016 0.3048 0.0254"/>
      </geometry>
      <origin xyz="0 0 -0.0127"/>
    </collision>
    <collision>
      <geometry>
        <box size="0.0508 0.3048 0.0254"/>
      </geometry>
      <origin xyz="-0.0508 0 -0.0254"/>
    </collision>
    <collision>
      <geometry>
        <box size="0.0508 0.3048 0.0254"/>
      </geometry>
      <origin xyz="0.0508 0 -0.0254"/>
    </collision>
    <inertial>
      <origin xyz="0 0 0"/>
      <mass value="1.0"/>
      <inertia ixx="0.001" ixy="0.0" ixz="0.0" iyy="0.001" iyz="0.0" izz="0.001"/>
    </inertial>
  </link>
  <!-- Legs -->
  <!-- Hip -->
  <link name="back_right_hip_link">
    <visual>
      <geometry>
        <mesh filename="file:///home/stewart/Robotics/ros-qp4/src/qp4_description/../../assets/cad/back_right_hip_s.dae"/>
      </geometry>
      <origin rpy="0 0 0" xyz="0.01 0.0 0"/>
    </visual>
    <!--
			   	<visual>
		   			<geometry>
						 <box size="0.06 0.06 0.06"/>
		   			</geometry>
					<origin xyz="${reflectx*(0.01)} ${ (reflecty*(-0.01))} -0.0128"/>
		   		</visual>
			-->
    <collision>
      <geometry>
        <box size="0.06 0.06 0.06"/>
      </geometry>
      <origin xyz="0.01 -0.01 -0.0128"/>
    </collision>
    <inertial>
      <origin xyz="0 0 0"/>
      <mass value="1.0"/>
      <inertia ixx="0.001" ixy="0.0" ixz="0.0" iyy="0.001" iyz="0.0" izz="0.001"/>
    </inertial>
  </link>
  <joint name="back_right_hip_swing_joint" type="revolute">
    <parent link="torso_link"/>
    <child link="back_right_hip_link"/>
    <origin rpy="0 0 0" xyz="0.0395 -0.1095 -0.0315"/>
    <axis xyz="0 -1 0"/>
    <limit effort="10" lower="-3.14159265359" upper="3.14159265359" velocity="1.0"/>
  </joint>
  <!-- Femur -->
  <link name="back_right_femur_link">
    <visual>
      <geometry>
        <mesh filename="file:///home/stewart/Robotics/ros-qp4/src/qp4_description/../../assets/cad/asb-09-black.dae" scale="0.001 0.001 0.001"/>
      </geometry>
      <origin rpy="0 0 0" xyz="0 0.0287 0"/>
    </visual>
    <visual>
      <geometry>
        <mesh filename="file:///home/stewart/Robotics/ros-qp4/src/qp4_description/../../assets/cad/asb-09-black.dae" scale="0.001 0.001 0.001"/>
      </geometry>
      <origin rpy="3.14159265359 0 0" xyz="0 0.0287 0"/>
    </visual>
    <!--
			   	<visual>
		   			<geometry>
						 <box size="0.0525 0.085 0.0254"/>
		   			</geometry>
					<origin xyz="0 0.028 0"/>				
		   		</visual>
			-->
    <collision>
      <geometry>
        <box size="0.0525 0.085 0.0254"/>
      </geometry>
      <origin xyz="0 0.028 0"/>
    </collision>
    <inertial>
      <origin xyz="0 0 0"/>
      <mass value="1.0"/>
      <inertia ixx="0.001" ixy="0.0" ixz="0.0" iyy="0.001" iyz="0.0" izz="0.001"/>
    </inertial>
  </link>
  <joint name="back_right_hip_lateral_joint" type="revolute">
    <parent link="back_right_hip_link"/>
    <child link="back_right_femur_link"/>
    <origin rpy="-1.57079632679 0 0" xyz="0.0192 0.0005 -0.0290"/>
    <limit effort="10" lower="-3.14159265359" upper="3.14159265359" velocity="1.0"/>
  </joint>
  <!-- Tibia -->
  <link name="back_right_tibia_link">
    <visual>
      <geometry>
        <mesh filename="file:///home/stewart/Robotics/ros-qp4/src/qp4_description/../../assets/cad/asb-15-black.dae" scale="0.001 0.001 0.001"/>
      </geometry>
      <origin rpy="0 -1.57079632679 0 " xyz="-0.0043 -0.01422 -0.0386"/>
    </visual>
    <visual>
      <geometry>
        <mesh filename="file:///home/stewart/Robotics/ros-qp4/src/qp4_description/../../assets/cad/hs-645-mg.dae" scale="0.001 0.001 0.001"/>
      </geometry>
      <origin rpy="1.57079632679 0 1.57079632679" xyz="0.0 0 -0.01"/>
    </visual>
    <visual>
      <geometry>
        <mesh filename="file:///home/stewart/Robotics/ros-qp4/src/qp4_description/../../assets/cad/hs-645-mg.dae" scale="0.001 0.001 0.001"/>
      </geometry>
      <origin rpy="-1.57079632679 0 -1.57079632679" xyz="0.0 0 -0.067"/>
    </visual>
    <!--
			   	<visual>
		   			<geometry>
						 <box size="0.0525 0.0254 0.115"/>
		   			</geometry>
					<origin xyz="${reflectx*(0.02)} 0 -0.039"/>				
		   		</visual>
			-->
    <collision>
      <geometry>
        <box size="0.0525 0.0254 0.115"/>
      </geometry>
      <origin xyz="0.02 0 -0.039"/>
    </collision>
    <inertial>
      <origin xyz="0 0 0"/>
      <mass value="1.0"/>
      <inertia ixx="0.001" ixy="0.0" ixz="0.0" iyy="0.001" iyz="0.0" izz="0.001"/>
    </inertial>
  </link>
  <joint name="back_right_knee_joint" type="revolute">
    <parent link="back_right_femur_link"/>
    <child link="back_right_tibia_link"/>
    <origin rpy="1.57079632679 0 0" xyz="-0.019 0.0572 0"/>
    <limit effort="10" lower="-3.14159265359" upper="3.14159265359" velocity="1.0"/>
  </joint>
  <!-- Foot -->
  <link name="back_right_foot_link">
    <visual>
      <geometry>
        <mesh filename="file:///home/stewart/Robotics/ros-qp4/src/qp4_description/../../assets/cad/asb-11.dae" scale="0.001 0.001 0.001"/>
      </geometry>
      <origin rpy="1.57079632679 0 3.14159265359" xyz="0 0.0185 -0.0272"/>
    </visual>
    <!--
			   	<visual>
		   			<geometry>
						 <box size="0.0523 0.0508 0.0400"/>
		   			</geometry>
					<origin xyz="0 0.01 -0.0072"/>
		   		</visual>
			-->
    <collision>
      <geometry>
        <box size="0.0523 0.0508 0.0400"/>
      </geometry>
      <origin xyz="0 0.01 -0.0072"/>
    </collision>
    <inertial>
      <origin xyz="0 0 0"/>
      <mass value="1.0"/>
      <inertia ixx="0.001" ixy="0.0" ixz="0.0" iyy="0.001" iyz="0.0" izz="0.001"/>
    </inertial>
  </link>
  <joint name="back_right_ankle_joint" type="revolute">
    <parent link="back_right_tibia_link"/>
    <child link="back_right_foot_link"/>
    <origin rpy="0 0 0" xyz="0.0185 -0.0002 -0.077"/>
    <limit effort="10" lower="-3.14159265359" upper="3.14159265359" velocity="1.0"/>
  </joint>
  <!-- Hip -->
  <link name="back_left_hip_link">
    <visual>
      <geometry>
        <mesh filename="file:///home/stewart/Robotics/ros-qp4/src/qp4_description/../../assets/cad/back_left_hip_s.dae"/>
      </geometry>
      <origin rpy="0 0 0" xyz="-0.01 0.0 0"/>
    </visual>
    <!--
			   	<visual>
		   			<geometry>
						 <box size="0.06 0.06 0.06"/>
		   			</geometry>
					<origin xyz="${reflectx*(0.01)} ${ (reflecty*(-0.01))} -0.0128"/>
		   		</visual>
			-->
    <collision>
      <geometry>
        <box size="0.06 0.06 0.06"/>
      </geometry>
      <origin xyz="-0.01 -0.01 -0.0128"/>
    </collision>
    <inertial>
      <origin xyz="0 0 0"/>
      <mass value="1.0"/>
      <inertia ixx="0.001" ixy="0.0" ixz="0.0" iyy="0.001" iyz="0.0" izz="0.001"/>
    </inertial>
  </link>
  <joint name="back_left_hip_swing_joint" type="revolute">
    <parent link="torso_link"/>
    <child link="back_left_hip_link"/>
    <origin rpy="0 0 0" xyz="-0.0395 -0.1095 -0.0315"/>
    <axis xyz="0 1 0"/>
    <limit effort="10" lower="-3.14159265359" upper="3.14159265359" velocity="1.0"/>
  </joint>
  <!-- Femur -->
  <link name="back_left_femur_link">
    <visual>
      <geometry>
        <mesh filename="file:///home/stewart/Robotics/ros-qp4/src/qp4_description/../../assets/cad/asb-09-black.dae" scale="0.001 0.001 0.001"/>
      </geometry>
      <origin rpy="0 0 0" xyz="0 0.0287 0"/>
    </visual>
    <visual>
      <geometry>
        <mesh filename="file:///home/stewart/Robotics/ros-qp4/src/qp4_description/../../assets/cad/asb-09-black.dae" scale="0.001 0.001 0.001"/>
      </geometry>
      <origin rpy="-3.14159265359 0 0" xyz="0 0.0287 0"/>
    </visual>
    <!--
			   	<visual>
		   			<geometry>
						 <box size="0.0525 0.085 0.0254"/>
		   			</geometry>
					<origin xyz="0 0.028 0"/>				
		   		</visual>
			-->
    <collision>
      <geometry>
        <box size="0.0525 0.085 0.0254"/>
      </geometry>
      <origin xyz="0 0.028 0"/>
    </collision>
    <inertial>
      <origin xyz="0 0 0"/>
      <mass value="1.0"/>
      <inertia ixx="0.001" ixy="0.0" ixz="0.0" iyy="0.001" iyz="0.0" izz="0.001"/>
    </inertial>
  </link>
  <joint name="back_left_hip_lateral_joint" type="revolute">
    <parent link="back_left_hip_link"/>
    <child link="back_left_femur_link"/>
    <origin rpy="-1.57079632679 0 0" xyz="-0.0192 0.0005 -0.0290"/>
    <limit effort="10" lower="-3.14159265359" upper="3.14159265359" velocity="1.0"/>
  </joint>
  <!-- Tibia -->
  <link name="back_left_tibia_link">
    <visual>
      <geometry>
        <mesh filename="file:///home/stewart/Robotics/ros-qp4/src/qp4_description/../../assets/cad/asb-15-black.dae" scale="0.001 0.001 0.001"/>
      </geometry>
      <origin rpy="0 1.57079632679 0 " xyz="0.0043 -0.01422 -0.0386"/>
    </visual>
    <visual>
      <geometry>
        <mesh filename="file:///home/stewart/Robotics/ros-qp4/src/qp4_description/../../assets/cad/hs-645-mg.dae" scale="0.001 0.001 0.001"/>
      </geometry>
      <origin rpy="1.57079632679 0 -1.57079632679" xyz="0.0 0 -0.01"/>
    </visual>
    <visual>
      <geometry>
        <mesh filename="file:///home/stewart/Robotics/ros-qp4/src/qp4_description/../../assets/cad/hs-645-mg.dae" scale="0.001 0.001 0.001"/>
      </geometry>
      <origin rpy="-1.57079632679 0 1.57079632679" xyz="0.0 0 -0.067"/>
    </visual>
    <!--
			   	<visual>
		   			<geometry>
						 <box size="0.0525 0.0254 0.115"/>
		   			</geometry>
					<origin xyz="${reflectx*(0.02)} 0 -0.039"/>				
		   		</visual>
			-->
    <collision>
      <geometry>
        <box size="0.0525 0.0254 0.115"/>
      </geometry>
      <origin xyz="-0.02 0 -0.039"/>
    </collision>
    <inertial>
      <origin xyz="0 0 0"/>
      <mass value="1.0"/>
      <inertia ixx="0.001" ixy="0.0" ixz="0.0" iyy="0.001" iyz="0.0" izz="0.001"/>
    </inertial>
  </link>
  <joint name="back_left_knee_joint" type="revolute">
    <parent link="back_left_femur_link"/>
    <child link="back_left_tibia_link"/>
    <origin rpy="1.57079632679 0 0" xyz="0.019 0.0572 0"/>
    <limit effort="10" lower="-3.14159265359" upper="3.14159265359" velocity="1.0"/>
  </joint>
  <!-- Foot -->
  <link name="back_left_foot_link">
    <visual>
      <geometry>
        <mesh filename="file:///home/stewart/Robotics/ros-qp4/src/qp4_description/../../assets/cad/asb-11.dae" scale="0.001 0.001 0.001"/>
      </geometry>
      <origin rpy="1.57079632679 0 3.14159265359" xyz="0 0.0185 -0.0272"/>
    </visual>
    <!--
			   	<visual>
		   			<geometry>
						 <box size="0.0523 0.0508 0.0400"/>
		   			</geometry>
					<origin xyz="0 0.01 -0.0072"/>
		   		</visual>
			-->
    <collision>
      <geometry>
        <box size="0.0523 0.0508 0.0400"/>
      </geometry>
      <origin xyz="0 0.01 -0.0072"/>
    </collision>
    <inertial>
      <origin xyz="0 0 0"/>
      <mass value="1.0"/>
      <inertia ixx="0.001" ixy="0.0" ixz="0.0" iyy="0.001" iyz="0.0" izz="0.001"/>
    </inertial>
  </link>
  <joint name="back_left_ankle_joint" type="revolute">
    <parent link="back_left_tibia_link"/>
    <child link="back_left_foot_link"/>
    <origin rpy="0 0 0" xyz="-0.0185 -0.0002 -0.077"/>
    <limit effort="10" lower="-3.14159265359" upper="3.14159265359" velocity="1.0"/>
  </joint>
  <!-- Hip -->
  <link name="front_right_hip_link">
    <visual>
      <geometry>
        <mesh filename="file:///home/stewart/Robotics/ros-qp4/src/qp4_description/../../assets/cad/front_right_hip_s.dae"/>
      </geometry>
      <origin rpy="0 0 0" xyz="0.01 0.02 0"/>
    </visual>
    <!--
			   	<visual>
		   			<geometry>
						 <box size="0.06 0.06 0.06"/>
		   			</geometry>
					<origin xyz="${reflectx*(0.01)} ${ (reflecty*(-0.01))} -0.0128"/>
		   		</visual>
			-->
    <collision>
      <geometry>
        <box size="0.06 0.06 0.06"/>
      </geometry>
      <origin xyz="0.01 0.01 -0.0128"/>
    </collision>
    <inertial>
      <origin xyz="0 0 0"/>
      <mass value="1.0"/>
      <inertia ixx="0.001" ixy="0.0" ixz="0.0" iyy="0.001" iyz="0.0" izz="0.001"/>
    </inertial>
  </link>
  <joint name="front_right_hip_swing_joint" type="revolute">
    <parent link="torso_link"/>
    <child link="front_right_hip_link"/>
    <origin rpy="0 0 0" xyz="0.0395 0.1095 -0.0315"/>
    <axis xyz="0 -1 0"/>
    <limit effort="10" lower="-3.14159265359" upper="3.14159265359" velocity="1.0"/>
  </joint>
  <!-- Femur -->
  <link name="front_right_femur_link">
    <visual>
      <geometry>
        <mesh filename="file:///home/stewart/Robotics/ros-qp4/src/qp4_description/../../assets/cad/asb-09-black.dae" scale="0.001 0.001 0.001"/>
      </geometry>
      <origin rpy="0 0 0" xyz="0 0.0287 0"/>
    </visual>
    <visual>
      <geometry>
        <mesh filename="file:///home/stewart/Robotics/ros-qp4/src/qp4_description/../../assets/cad/asb-09-black.dae" scale="0.001 0.001 0.001"/>
      </geometry>
      <origin rpy="3.14159265359 0 0" xyz="0 0.0287 0"/>
    </visual>
    <!--
			   	<visual>
		   			<geometry>
						 <box size="0.0525 0.085 0.0254"/>
		   			</geometry>
					<origin xyz="0 0.028 0"/>				
		   		</visual>
			-->
    <collision>
      <geometry>
        <box size="0.0525 0.085 0.0254"/>
      </geometry>
      <origin xyz="0 0.028 0"/>
    </collision>
    <inertial>
      <origin xyz="0 0 0"/>
      <mass value="1.0"/>
      <inertia ixx="0.001" ixy="0.0" ixz="0.0" iyy="0.001" iyz="0.0" izz="0.001"/>
    </inertial>
  </link>
  <joint name="front_right_hip_lateral_joint" type="revolute">
    <parent link="front_right_hip_link"/>
    <child link="front_right_femur_link"/>
    <origin rpy="-1.57079632679 0 0" xyz="0.0192 0.0005 -0.0290"/>
    <limit effort="10" lower="-3.14159265359" upper="3.14159265359" velocity="1.0"/>
  </joint>
  <!-- Tibia -->
  <link name="front_right_tibia_link">
    <visual>
      <geometry>
        <mesh filename="file:///home/stewart/Robotics/ros-qp4/src/qp4_description/../../assets/cad/asb-15-black.dae" scale="0.001 0.001 0.001"/>
      </geometry>
      <origin rpy="0 -1.57079632679 0 " xyz="-0.0043 -0.01422 -0.0386"/>
    </visual>
    <visual>
      <geometry>
        <mesh filename="file:///home/stewart/Robotics/ros-qp4/src/qp4_description/../../assets/cad/hs-645-mg.dae" scale="0.001 0.001 0.001"/>
      </geometry>
      <origin rpy="1.57079632679 0 1.57079632679" xyz="0.0 0 -0.01"/>
    </visual>
    <visual>
      <geometry>
        <mesh filename="file:///home/stewart/Robotics/ros-qp4/src/qp4_description/../../assets/cad/hs-645-mg.dae" scale="0.001 0.001 0.001"/>
      </geometry>
      <origin rpy="-1.57079632679 0 -1.57079632679" xyz="0.0 0 -0.067"/>
    </visual>
    <!--
			   	<visual>
		   			<geometry>
						 <box size="0.0525 0.0254 0.115"/>
		   			</geometry>
					<origin xyz="${reflectx*(0.02)} 0 -0.039"/>				
		   		</visual>
			-->
    <collision>
      <geometry>
        <box size="0.0525 0.0254 0.115"/>
      </geometry>
      <origin xyz="0.02 0 -0.039"/>
    </collision>
    <inertial>
      <origin xyz="0 0 0"/>
      <mass value="1.0"/>
      <inertia ixx="0.001" ixy="0.0" ixz="0.0" iyy="0.001" iyz="0.0" izz="0.001"/>
    </inertial>
  </link>
  <joint name="front_right_knee_joint" type="revolute">
    <parent link="front_right_femur_link"/>
    <child link="front_right_tibia_link"/>
    <origin rpy="1.57079632679 0 0" xyz="-0.019 0.0572 0"/>
    <limit effort="10" lower="-3.14159265359" upper="3.14159265359" velocity="1.0"/>
  </joint>
  <!-- Foot -->
  <link name="front_right_foot_link">
    <visual>
      <geometry>
        <mesh filename="file:///home/stewart/Robotics/ros-qp4/src/qp4_description/../../assets/cad/asb-11.dae" scale="0.001 0.001 0.001"/>
      </geometry>
      <origin rpy="1.57079632679 0 3.14159265359" xyz="0 0.0185 -0.0272"/>
    </visual>
    <!--
			   	<visual>
		   			<geometry>
						 <box size="0.0523 0.0508 0.0400"/>
		   			</geometry>
					<origin xyz="0 0.01 -0.0072"/>
		   		</visual>
			-->
    <collision>
      <geometry>
        <box size="0.0523 0.0508 0.0400"/>
      </geometry>
      <origin xyz="0 0.01 -0.0072"/>
    </collision>
    <inertial>
      <origin xyz="0 0 0"/>
      <mass value="1.0"/>
      <inertia ixx="0.001" ixy="0.0" ixz="0.0" iyy="0.001" iyz="0.0" izz="0.001"/>
    </inertial>
  </link>
  <joint name="front_right_ankle_joint" type="revolute">
    <parent link="front_right_tibia_link"/>
    <child link="front_right_foot_link"/>
    <origin rpy="0 0 0" xyz="0.0185 0.0002 -0.077"/>
    <limit effort="10" lower="-3.14159265359" upper="3.14159265359" velocity="1.0"/>
  </joint>
  <!-- Hip -->
  <link name="front_left_hip_link">
    <visual>
      <geometry>
        <mesh filename="file:///home/stewart/Robotics/ros-qp4/src/qp4_description/../../assets/cad/front_left_hip_s.dae"/>
      </geometry>
      <origin rpy="0 0 0" xyz="-0.01 0.02 0"/>
    </visual>
    <!--
			   	<visual>
		   			<geometry>
						 <box size="0.06 0.06 0.06"/>
		   			</geometry>
					<origin xyz="${reflectx*(0.01)} ${ (reflecty*(-0.01))} -0.0128"/>
		   		</visual>
			-->
    <collision>
      <geometry>
        <box size="0.06 0.06 0.06"/>
      </geometry>
      <origin xyz="-0.01 0.01 -0.0128"/>
    </collision>
    <inertial>
      <origin xyz="0 0 0"/>
      <mass value="1.0"/>
      <inertia ixx="0.001" ixy="0.0" ixz="0.0" iyy="0.001" iyz="0.0" izz="0.001"/>
    </inertial>
  </link>
  <joint name="front_left_hip_swing_joint" type="revolute">
    <parent link="torso_link"/>
    <child link="front_left_hip_link"/>
    <origin rpy="0 0 0" xyz="-0.0395 0.1095 -0.0315"/>
    <axis xyz="0 1 0"/>
    <limit effort="10" lower="-3.14159265359" upper="3.14159265359" velocity="1.0"/>
  </joint>
  <!-- Femur -->
  <link name="front_left_femur_link">
    <visual>
      <geometry>
        <mesh filename="file:///home/stewart/Robotics/ros-qp4/src/qp4_description/../../assets/cad/asb-09-black.dae" scale="0.001 0.001 0.001"/>
      </geometry>
      <origin rpy="0 0 0" xyz="0 0.0287 0"/>
    </visual>
    <visual>
      <geometry>
        <mesh filename="file:///home/stewart/Robotics/ros-qp4/src/qp4_description/../../assets/cad/asb-09-black.dae" scale="0.001 0.001 0.001"/>
      </geometry>
      <origin rpy="-3.14159265359 0 0" xyz="0 0.0287 0"/>
    </visual>
    <!--
			   	<visual>
		   			<geometry>
						 <box size="0.0525 0.085 0.0254"/>
		   			</geometry>
					<origin xyz="0 0.028 0"/>				
		   		</visual>
			-->
    <collision>
      <geometry>
        <box size="0.0525 0.085 0.0254"/>
      </geometry>
      <origin xyz="0 0.028 0"/>
    </collision>
    <inertial>
      <origin xyz="0 0 0"/>
      <mass value="1.0"/>
      <inertia ixx="0.001" ixy="0.0" ixz="0.0" iyy="0.001" iyz="0.0" izz="0.001"/>
    </inertial>
  </link>
  <joint name="front_left_hip_lateral_joint" type="revolute">
    <parent link="front_left_hip_link"/>
    <child link="front_left_femur_link"/>
    <origin rpy="-1.57079632679 0 0" xyz="-0.0192 0.0005 -0.0290"/>
    <limit effort="10" lower="-3.14159265359" upper="3.14159265359" velocity="1.0"/>
  </joint>
  <!-- Tibia -->
  <link name="front_left_tibia_link">
    <visual>
      <geometry>
        <mesh filename="file:///home/stewart/Robotics/ros-qp4/src/qp4_description/../../assets/cad/asb-15-black.dae" scale="0.001 0.001 0.001"/>
      </geometry>
      <origin rpy="0 1.57079632679 0 " xyz="0.0043 -0.01422 -0.0386"/>
    </visual>
    <visual>
      <geometry>
        <mesh filename="file:///home/stewart/Robotics/ros-qp4/src/qp4_description/../../assets/cad/hs-645-mg.dae" scale="0.001 0.001 0.001"/>
      </geometry>
      <origin rpy="1.57079632679 0 -1.57079632679" xyz="0.0 0 -0.01"/>
    </visual>
    <visual>
      <geometry>
        <mesh filename="file:///home/stewart/Robotics/ros-qp4/src/qp4_description/../../assets/cad/hs-645-mg.dae" scale="0.001 0.001 0.001"/>
      </geometry>
      <origin rpy="-1.57079632679 0 1.57079632679" xyz="0.0 0 -0.067"/>
    </visual>
    <!--
			   	<visual>
		   			<geometry>
						 <box size="0.0525 0.0254 0.115"/>
		   			</geometry>
					<origin xyz="${reflectx*(0.02)} 0 -0.039"/>				
		   		</visual>
			-->
    <collision>
      <geometry>
        <box size="0.0525 0.0254 0.115"/>
      </geometry>
      <origin xyz="-0.02 0 -0.039"/>
    </collision>
    <inertial>
      <origin xyz="0 0 0"/>
      <mass value="1.0"/>
      <inertia ixx="0.001" ixy="0.0" ixz="0.0" iyy="0.001" iyz="0.0" izz="0.001"/>
    </inertial>
  </link>
  <joint name="front_left_knee_joint" type="revolute">
    <parent link="front_left_femur_link"/>
    <child link="front_left_tibia_link"/>
    <origin rpy="1.57079632679 0 0" xyz="0.019 0.0572 0"/>
    <limit effort="10" lower="-3.14159265359" upper="3.14159265359" velocity="1.0"/>
  </joint>
  <!-- Foot -->
  <link name="front_left_foot_link">
    <visual>
      <geometry>
        <mesh filename="file:///home/stewart/Robotics/ros-qp4/src/qp4_description/../../assets/cad/asb-11.dae" scale="0.001 0.001 0.001"/>
      </geometry>
      <origin rpy="1.57079632679 0 3.14159265359" xyz="0 0.0185 -0.0272"/>
    </visual>
    <!--
			   	<visual>
		   			<geometry>
						 <box size="0.0523 0.0508 0.0400"/>
		   			</geometry>
					<origin xyz="0 0.01 -0.0072"/>
		   		</visual>
			-->
    <collision>
      <geometry>
        <box size="0.0523 0.0508 0.0400"/>
      </geometry>
      <origin xyz="0 0.01 -0.0072"/>
    </collision>
    <inertial>
      <origin xyz="0 0 0"/>
      <mass value="1.0"/>
      <inertia ixx="0.001" ixy="0.0" ixz="0.0" iyy="0.001" iyz="0.0" izz="0.001"/>
    </inertial>
  </link>
  <joint name="front_left_ankle_joint" type="revolute">
    <parent link="front_left_tibia_link"/>
    <child link="front_left_foot_link"/>
    <origin rpy="0 0 0" xyz="-0.0185 0.0002 -0.077"/>
    <limit effort="10" lower="-3.14159265359" upper="3.14159265359" velocity="1.0"/>
  </joint>
  <link name="base_link"/>
  <joint name="base_to_torso" type="fixed">
    <parent link="base_link"/>
    <child link="torso_link"/>
    <origin xyz="0 0 0.22"/>
  </joint>
</robot>
